<?xml version="1.0" ?>
<!-- =================================================================================== -->
<!-- |    This document was autogenerated by xacro from manta.xacro.urdf            | -->
<!-- |    EDITING THIS FILE BY HAND IS NOT RECOMMENDED                                 | -->
<!-- =================================================================================== -->
<robot name="manta_v2">
  <material name="silver">
    <color rgba="0.700 0.700 0.700 1.000"/>
  </material>
  <material name="white">
    <color rgba="1.0 1.0 1.0 1.0"/>
  </material>
  <material name="grey">
    <color rgba="0.2 0.2 0.2 1.0"/>
  </material>

  <transmission name="rev_link_head_tran">
    <type>transmission_interface/SimpleTransmission</type>
    <joint name="rev_link_head">
      <hardwareInterface>hardware_interface/EffortJointInterface</hardwareInterface>
    </joint>
    <actuator name="rev_link_head_actr">
      <hardwareInterface>hardware_interface/EffortJointInterface</hardwareInterface>
      <mechanicalReduction>1</mechanicalReduction>
    </actuator>
  </transmission>

  <transmission name="rev_link_Ltop_roll2_tran">
    <type>transmission_interface/SimpleTransmission</type>
    <joint name="rev_link_Ltop_roll2">
      <hardwareInterface>hardware_interface/EffortJointInterface</hardwareInterface>
    </joint>
    <actuator name="rev_link_Ltop_roll2_actr">
      <hardwareInterface>hardware_interface/EffortJointInterface</hardwareInterface>
      <mechanicalReduction>1</mechanicalReduction>
    </actuator>
  </transmission>

  <transmission name="rev_link_Ltop_pitch_tran">
    <type>transmission_interface/SimpleTransmission</type>
    <joint name="rev_link_Ltop_pitch">
      <hardwareInterface>hardware_interface/EffortJointInterface</hardwareInterface>
    </joint>
    <actuator name="rev_link_Ltop_pitch_actr">
      <hardwareInterface>hardware_interface/EffortJointInterface</hardwareInterface>
      <mechanicalReduction>1</mechanicalReduction>
    </actuator>
  </transmission>

  <transmission name="rev_link_Ltop_roll1_tran">
    <type>transmission_interface/SimpleTransmission</type>
    <joint name="rev_link_Ltop_roll1">
      <hardwareInterface>hardware_interface/EffortJointInterface</hardwareInterface>
    </joint>
    <actuator name="rev_link_Ltop_roll1_actr">
      <hardwareInterface>hardware_interface/EffortJointInterface</hardwareInterface>
      <mechanicalReduction>1</mechanicalReduction>
    </actuator>
  </transmission>

  <transmission name="rev_link_Lmid_roll2_tran">
    <type>transmission_interface/SimpleTransmission</type>
    <joint name="rev_link_Lmid_roll2">
      <hardwareInterface>hardware_interface/EffortJointInterface</hardwareInterface>
    </joint>
    <actuator name="rev_link_Lmid_roll2_actr">
      <hardwareInterface>hardware_interface/EffortJointInterface</hardwareInterface>
      <mechanicalReduction>1</mechanicalReduction>
    </actuator>
  </transmission>

  <transmission name="rev_link_Lmid_pitch_tran">
    <type>transmission_interface/SimpleTransmission</type>
    <joint name="rev_link_Lmid_pitch">
      <hardwareInterface>hardware_interface/EffortJointInterface</hardwareInterface>
    </joint>
    <actuator name="rev_link_Lmid_pitch_actr">
      <hardwareInterface>hardware_interface/EffortJointInterface</hardwareInterface>
      <mechanicalReduction>1</mechanicalReduction>
    </actuator>
  </transmission>

  <transmission name="rev_link_Lmid_roll1_tran">
    <type>transmission_interface/SimpleTransmission</type>
    <joint name="rev_link_Lmid_roll1">
      <hardwareInterface>hardware_interface/EffortJointInterface</hardwareInterface>
    </joint>
    <actuator name="rev_link_Lmid_roll1_actr">
      <hardwareInterface>hardware_interface/EffortJointInterface</hardwareInterface>
      <mechanicalReduction>1</mechanicalReduction>
    </actuator>
  </transmission>

  <transmission name="rev_link_Lbtm_roll2_tran">
    <type>transmission_interface/SimpleTransmission</type>
    <joint name="rev_link_Lbtm_roll2">
      <hardwareInterface>hardware_interface/EffortJointInterface</hardwareInterface>
    </joint>
    <actuator name="rev_link_Lbtm_roll2_actr">
      <hardwareInterface>hardware_interface/EffortJointInterface</hardwareInterface>
      <mechanicalReduction>1</mechanicalReduction>
    </actuator>
  </transmission>

  <transmission name="rev_link_Lbtm_pitch_tran">
    <type>transmission_interface/SimpleTransmission</type>
    <joint name="rev_link_Lbtm_pitch">
      <hardwareInterface>hardware_interface/EffortJointInterface</hardwareInterface>
    </joint>
    <actuator name="rev_link_Lbtm_pitch_actr">
      <hardwareInterface>hardware_interface/EffortJointInterface</hardwareInterface>
      <mechanicalReduction>1</mechanicalReduction>
    </actuator>
  </transmission>

  <transmission name="rev_link_Lbtm_roll1_tran">
    <type>transmission_interface/SimpleTransmission</type>
    <joint name="rev_link_Lbtm_roll1">
      <hardwareInterface>hardware_interface/EffortJointInterface</hardwareInterface>
    </joint>
    <actuator name="rev_link_Lbtm_roll1_actr">
      <hardwareInterface>hardware_interface/EffortJointInterface</hardwareInterface>
      <mechanicalReduction>1</mechanicalReduction>
    </actuator>
  </transmission>

  <transmission name="rev_link_Rtop_roll2_tran">
    <type>transmission_interface/SimpleTransmission</type>
    <joint name="rev_link_Rtop_roll2">
      <hardwareInterface>hardware_interface/EffortJointInterface</hardwareInterface>
    </joint>
    <actuator name="rev_link_Rtop_roll2_actr">
      <hardwareInterface>hardware_interface/EffortJointInterface</hardwareInterface>
      <mechanicalReduction>1</mechanicalReduction>
    </actuator>
  </transmission>

  <transmission name="rev_link_Rtop_pitch_tran">
    <type>transmission_interface/SimpleTransmission</type>
    <joint name="rev_link_Rtop_pitch">
      <hardwareInterface>hardware_interface/EffortJointInterface</hardwareInterface>
    </joint>
    <actuator name="rev_link_Rtop_pitch_actr">
      <hardwareInterface>hardware_interface/EffortJointInterface</hardwareInterface>
      <mechanicalReduction>1</mechanicalReduction>
    </actuator>
  </transmission>

  <transmission name="rev_link_Rtop_roll1_tran">
    <type>transmission_interface/SimpleTransmission</type>
    <joint name="rev_link_Rtop_roll1">
      <hardwareInterface>hardware_interface/EffortJointInterface</hardwareInterface>
    </joint>
    <actuator name="rev_link_Rtop_roll1_actr">
      <hardwareInterface>hardware_interface/EffortJointInterface</hardwareInterface>
      <mechanicalReduction>1</mechanicalReduction>
    </actuator>
  </transmission>

  <transmission name="rev_link_Rmid_roll2_tran">
    <type>transmission_interface/SimpleTransmission</type>
    <joint name="rev_link_Rmid_roll2">
      <hardwareInterface>hardware_interface/EffortJointInterface</hardwareInterface>
    </joint>
    <actuator name="rev_link_Rmid_roll2_actr">
      <hardwareInterface>hardware_interface/EffortJointInterface</hardwareInterface>
      <mechanicalReduction>1</mechanicalReduction>
    </actuator>
  </transmission>

  <transmission name="rev_link_Rmid_pitch_tran">
    <type>transmission_interface/SimpleTransmission</type>
    <joint name="rev_link_Rmid_pitch">
      <hardwareInterface>hardware_interface/EffortJointInterface</hardwareInterface>
    </joint>
    <actuator name="rev_link_Rmid_pitch_actr">
      <hardwareInterface>hardware_interface/EffortJointInterface</hardwareInterface>
      <mechanicalReduction>1</mechanicalReduction>
    </actuator>
  </transmission>

  <transmission name="rev_link_Rmid_roll1_tran">
    <type>transmission_interface/SimpleTransmission</type>
    <joint name="rev_link_Rmid_roll1">
      <hardwareInterface>hardware_interface/EffortJointInterface</hardwareInterface>
    </joint>
    <actuator name="rev_link_Rmid_roll1_actr">
      <hardwareInterface>hardware_interface/EffortJointInterface</hardwareInterface>
      <mechanicalReduction>1</mechanicalReduction>
    </actuator>
  </transmission>

  <transmission name="rev_link_Rbtm_roll2_tran">
    <type>transmission_interface/SimpleTransmission</type>
    <joint name="rev_link_Rbtm_roll2">
      <hardwareInterface>hardware_interface/EffortJointInterface</hardwareInterface>
    </joint>
    <actuator name="rev_link_Rbtm_roll2_actr">
      <hardwareInterface>hardware_interface/EffortJointInterface</hardwareInterface>
      <mechanicalReduction>1</mechanicalReduction>
    </actuator>
  </transmission>

  <transmission name="rev_link_Rbtm_pitch_tran">
    <type>transmission_interface/SimpleTransmission</type>
    <joint name="rev_link_Rbtm_pitch">
      <hardwareInterface>hardware_interface/EffortJointInterface</hardwareInterface>
    </joint>
    <actuator name="rev_link_Rbtm_pitch_actr">
      <hardwareInterface>hardware_interface/EffortJointInterface</hardwareInterface>
      <mechanicalReduction>1</mechanicalReduction>
    </actuator>
  </transmission>

  <transmission name="rev_link_Rbtm_roll1_tran">
    <type>transmission_interface/SimpleTransmission</type>
    <joint name="rev_link_Rbtm_roll1">
      <hardwareInterface>hardware_interface/EffortJointInterface</hardwareInterface>
    </joint>
    <actuator name="rev_link_Rbtm_roll1_actr">
      <hardwareInterface>hardware_interface/EffortJointInterface</hardwareInterface>
      <mechanicalReduction>1</mechanicalReduction>
    </actuator>
  </transmission>

  <gazebo reference="base_link">
    <material>Gazebo/Grey</material>
        <gravity>0</gravity>
        <kp>1e10</kp>
        <kd>1e10</kd>
        <mu1>2000.0</mu1>
        <mu2>2000.0</mu2>
        <fdir1>0 0 1</fdir1>
        <maxVel>1.0</maxVel>
        <minDepth>0.001</minDepth>
    <selfCollide>true</selfCollide>
    <gravity>true</gravity>
  </gazebo>

  <gazebo reference="link_ballast_1">
    <material>Gazebo/White</material>
        <gravity>0</gravity>
        <kp>1e10</kp>
        <kd>1e10</kd>
        <mu1>2000.0</mu1>
        <mu2>2000.0</mu2>
        <fdir1>0 0 1</fdir1>
        <maxVel>1.0</maxVel>
        <minDepth>0.001</minDepth>
    <selfCollide>true</selfCollide>
  </gazebo>



  <joint name="camera_joint" type="fixed">
    <axis xyz="0 1 0" />
    <origin xyz="0.03 0 0.01" rpy="0 0 0"/>
    <parent link="link_rs_camera_1"/>
    <child link="camera_link"/>
  </joint>

  <!-- Camera -->
  <link name="camera_link">
    <collision>
      <origin xyz="0 0 0" rpy="0 0 0"/>
      <geometry>
    <box size="0.0 0.0 0.0"/>
      </geometry>
    </collision>

    <visual>
      <origin xyz="0 0 0" rpy="0 0 0"/>
      <geometry>
    <box size="0.01 0.01 0.01"/>
      </geometry>
      <material name="gray"/>
    </visual>

    <inertial>
      <mass value="1e-5" />
      <origin xyz="0 0 0" rpy="0 0 0"/>
      <inertia ixx="1e-6" ixy="0" ixz="0" iyy="1e-6" iyz="0" izz="1e-6" />
    </inertial>
  </link>

  <gazebo reference="camera_link">
    <material>Gazebo/Grey</material>
        <gravity>0</gravity>
        <kp>1e10</kp>
        <kd>1e10</kd>
        <mu1>2000.0</mu1>
        <mu2>2000.0</mu2>
        <fdir1>0 0 1</fdir1>
        <maxVel>1.0</maxVel>
        <minDepth>0.001</minDepth>
    <selfCollide>true</selfCollide>

    <sensor type="camera" name="camera">
      <update_rate>30.0</update_rate>
      <camera name="rs_camera">
        <horizontal_fov>1.3962634</horizontal_fov>
        <image>
          <width>1920</width>
          <height>1080</height>
          <format>R8G8B8</format>
        </image>
        <clip>
          <near>0.02</near>
          <far>300</far>
        </clip>
        <noise>
          <type>gaussian</type>
          <!-- Noise is sampled independently per pixel on each frame.
               That pixel's noise value is added to each of its color
               channels, which at that point lie in the range [0,1]. -->
          <mean>0.0</mean>
          <stddev>0.007</stddev>
        </noise>
      </camera>
      <plugin name="camera_controller" filename="libgazebo_ros_camera.so">
        <alwaysOn>true</alwaysOn>
        <updateRate>30.0</updateRate>
        <cameraName>camera</cameraName>
        <imageTopicName>image_raw</imageTopicName>
        <cameraInfoTopicName>camera_info</cameraInfoTopicName>
        <frameName>camera_link</frameName>
        <hackBaseline>0.07</hackBaseline>
        <distortionK1>0.0</distortionK1>
        <distortionK2>0.0</distortionK2>
        <distortionK3>0.0</distortionK3>
        <distortionT1>0.0</distortionT1>
        <distortionT2>0.0</distortionT2>
      </plugin>
    </sensor>
  </gazebo>

  <gazebo reference="link_rs_camera_1">
    <material>Gazebo/Grey</material>
        <gravity>0</gravity>
        <kp>1e10</kp>
        <kd>1e10</kd>
        <mu1>2000.0</mu1>
        <mu2>2000.0</mu2>
        <fdir1>0 0 1</fdir1>
        <maxVel>1.0</maxVel>
        <minDepth>0.001</minDepth>
    <selfCollide>true</selfCollide>
  </gazebo>

  <gazebo reference="link_head_1">
    <material>Gazebo/Grey</material>
        <gravity>0</gravity>
        <kp>1e10</kp>
        <kd>1e10</kd>
        <mu1>2000.0</mu1>
        <mu2>2000.0</mu2>
        <fdir1>0 0 1</fdir1>
        <maxVel>1.0</maxVel>
        <minDepth>0.001</minDepth>
    <selfCollide>true</selfCollide>
  </gazebo>

  <gazebo reference="link_Ltop_end_1">
    <material>Gazebo/White</material>
        <gravity>1</gravity>
        <kp>1e10</kp>
        <kd>1e10</kd>
        <mu1>2000.0</mu1>
        <mu2>2000.0</mu2>
        <fdir1>0 0 1</fdir1>
        <maxVel>1.0</maxVel>
        <minDepth>0.001</minDepth>
    <selfCollide>true</selfCollide>
  </gazebo>

  <gazebo reference="link_Ltop_roll2_1">
    <material>Gazebo/White</material>
        <gravity>1</gravity>
        <kp>1e10</kp>
        <kd>1e10</kd>
        <mu1>2000.0</mu1>
        <mu2>2000.0</mu2>
        <fdir1>0 0 1</fdir1>
        <maxVel>1.0</maxVel>
        <minDepth>0.001</minDepth>
    <selfCollide>true</selfCollide>
  </gazebo>

  <gazebo reference="link_Ltop_pitch_1">
    <material>Gazebo/Grey</material>
        <gravity>0</gravity>
        <kp>1e10</kp>
        <kd>1e10</kd>
        <mu1>2000.0</mu1>
        <mu2>2000.0</mu2>
        <fdir1>0 0 1</fdir1>
        <maxVel>1.0</maxVel>
        <minDepth>0.001</minDepth>
    <selfCollide>true</selfCollide>
  </gazebo>

  <gazebo reference="link_Ltop_roll1_1">
    <material>Gazebo/Grey</material>
        <gravity>0</gravity>
        <kp>1e10</kp>
        <kd>1e10</kd>
        <mu1>2000.0</mu1>
        <mu2>2000.0</mu2>
        <fdir1>0 0 1</fdir1>
        <maxVel>1.0</maxVel>
        <minDepth>0.001</minDepth>
    <selfCollide>true</selfCollide>
  </gazebo>

  <gazebo reference="link_Lmid_end_1">
    <material>Gazebo/White</material>
        <gravity>1</gravity>
        <kp>1e10</kp>
        <kd>1e10</kd>
        <mu1>2000.0</mu1>
        <mu2>2000.0</mu2>
        <fdir1>0 0 1</fdir1>
        <maxVel>1.0</maxVel>
        <minDepth>0.001</minDepth>
    <selfCollide>true</selfCollide>
  </gazebo>

  <gazebo reference="link_Lmid_roll2_1">
    <material>Gazebo/White</material>
        <gravity>1</gravity>
        <kp>1e10</kp>
        <kd>1e10</kd>
        <mu1>2000.0</mu1>
        <mu2>2000.0</mu2>
        <fdir1>0 0 1</fdir1>
        <maxVel>1.0</maxVel>
        <minDepth>0.001</minDepth>
    <selfCollide>true</selfCollide>
  </gazebo>

  <gazebo reference="link_Lmid_pitch_1">
    <material>Gazebo/Grey</material>
        <gravity>1</gravity>
        <kp>1e10</kp>
        <kd>1e10</kd>
        <mu1>2000.0</mu1>
        <mu2>2000.0</mu2>
        <fdir1>0 0 1</fdir1>
        <maxVel>1.0</maxVel>
        <minDepth>0.001</minDepth>
    <selfCollide>true</selfCollide>
  </gazebo>

  <gazebo reference="link_Lmid_roll1_1">
    <material>Gazebo/Grey</material>
        <gravity>1</gravity>
        <kp>1e10</kp>
        <kd>1e10</kd>
        <mu1>2000.0</mu1>
        <mu2>2000.0</mu2>
        <fdir1>0 0 1</fdir1>
        <maxVel>1.0</maxVel>
        <minDepth>0.001</minDepth>
    <selfCollide>true</selfCollide>
  </gazebo>

  <gazebo reference="link_Lbtm_end_1">
    <material>Gazebo/White</material>
        <gravity>1</gravity>
        <kp>1e10</kp>
        <kd>1e10</kd>
        <mu1>2000.0</mu1>
        <mu2>2000.0</mu2>
        <fdir1>0 0 1</fdir1>
        <maxVel>1.0</maxVel>
        <minDepth>0.001</minDepth>
    <selfCollide>true</selfCollide>
  </gazebo>

  <gazebo reference="link_Lbtm_roll2_1">
    <material>Gazebo/White</material>
        <gravity>1</gravity>
        <kp>1e10</kp>
        <kd>1e10</kd>
        <mu1>2000.0</mu1>
        <mu2>2000.0</mu2>
        <fdir1>0 0 1</fdir1>
        <maxVel>1.0</maxVel>
        <minDepth>0.001</minDepth>
    <selfCollide>true</selfCollide>
  </gazebo>

  <gazebo reference="link_Lbtm_pitch_1">
    <material>Gazebo/Grey</material>
        <gravity>1</gravity>
        <kp>1e10</kp>
        <kd>1e10</kd>
        <mu1>2000.0</mu1>
        <mu2>2000.0</mu2>
        <fdir1>0 0 1</fdir1>
        <maxVel>1.0</maxVel>
        <minDepth>0.001</minDepth>
    <selfCollide>true</selfCollide>
  </gazebo>

  <gazebo reference="link_Lbtm_roll1_1">
    <material>Gazebo/Grey</material>
        <gravity>1</gravity>
        <kp>1e10</kp>
        <kd>1e10</kd>
        <mu1>2000.0</mu1>
        <mu2>2000.0</mu2>
        <fdir1>0 0 1</fdir1>
        <maxVel>1.0</maxVel>
        <minDepth>0.001</minDepth>
    <selfCollide>true</selfCollide>
  </gazebo>

  <gazebo reference="link_Rtop_end_1">
    <material>Gazebo/White</material>
        <gravity>1</gravity>
        <kp>1e10</kp>
        <kd>1e10</kd>
        <mu1>2000.0</mu1>
        <mu2>2000.0</mu2>
        <fdir1>0 0 1</fdir1>
        <maxVel>1.0</maxVel>
        <minDepth>0.001</minDepth>
    <selfCollide>true</selfCollide>
  </gazebo>

  <gazebo reference="link_Rtop_roll2_1">
    <material>Gazebo/White</material>
        <gravity>1</gravity>
        <kp>1e10</kp>
        <kd>1e10</kd>
        <mu1>2000.0</mu1>
        <mu2>2000.0</mu2>
        <fdir1>0 0 1</fdir1>
        <maxVel>1.0</maxVel>
        <minDepth>0.001</minDepth>
    <selfCollide>true</selfCollide>
  </gazebo>

  <gazebo reference="link_Rtop_pitch_1">
    <material>Gazebo/Grey</material>
        <gravity>0</gravity>
        <kp>1e10</kp>
        <kd>1e10</kd>
        <mu1>2000.0</mu1>
        <mu2>2000.0</mu2>
        <fdir1>0 0 1</fdir1>
        <maxVel>1.0</maxVel>
        <minDepth>0.001</minDepth>
    <selfCollide>true</selfCollide>
  </gazebo>

  <gazebo reference="link_Rtop_roll1_1">
    <material>Gazebo/Grey</material>
        <gravity>0</gravity>
        <kp>1e10</kp>
        <kd>1e10</kd>
        <mu1>2000.0</mu1>
        <mu2>2000.0</mu2>
        <fdir1>0 0 1</fdir1>
        <maxVel>1.0</maxVel>
        <minDepth>0.001</minDepth>
    <selfCollide>true</selfCollide>
  </gazebo>

  <gazebo reference="link_Rmid_end_1">
    <material>Gazebo/White</material>
        <gravity>1</gravity>
        <kp>1e10</kp>
        <kd>1e10</kd>
        <mu1>2000.0</mu1>
        <mu2>2000.0</mu2>
        <fdir1>0 0 1</fdir1>
        <maxVel>1.0</maxVel>
        <minDepth>0.001</minDepth>
    <selfCollide>true</selfCollide>
  </gazebo>

  <gazebo reference="link_Rmid_roll2_1">
    <material>Gazebo/White</material>
        <gravity>1</gravity>
        <kp>1e10</kp>
        <kd>1e10</kd>
        <mu1>2000.0</mu1>
        <mu2>2000.0</mu2>
        <fdir1>0 0 1</fdir1>
        <maxVel>1.0</maxVel>
        <minDepth>0.001</minDepth>
    <selfCollide>true</selfCollide>
  </gazebo>

  <gazebo reference="link_Rmid_pitch_1">
    <material>Gazebo/Grey</material>
        <gravity>1</gravity>
        <kp>1e10</kp>
        <kd>1e10</kd>
        <mu1>2000.0</mu1>
        <mu2>2000.0</mu2>
        <fdir1>0 0 1</fdir1>
        <maxVel>1.0</maxVel>
        <minDepth>0.001</minDepth>
    <selfCollide>true</selfCollide>
  </gazebo>

  <gazebo reference="link_Rmid_roll1_1">
    <material>Gazebo/Grey</material>
        <gravity>1</gravity>
        <kp>1e10</kp>
        <kd>1e10</kd>
        <mu1>2000.0</mu1>
        <mu2>2000.0</mu2>
        <fdir1>0 0 1</fdir1>
        <maxVel>1.0</maxVel>
        <minDepth>0.001</minDepth>
    <selfCollide>true</selfCollide>
  </gazebo>

  <gazebo reference="link_Rbtm_end_1">
    <material>Gazebo/White</material>
        <gravity>1</gravity>
        <kp>1e10</kp>
        <kd>1e10</kd>
        <mu1>2000.0</mu1>
        <mu2>2000.0</mu2>
        <fdir1>0 0 1</fdir1>
        <maxVel>1.0</maxVel>
        <minDepth>0.001</minDepth>
    <selfCollide>true</selfCollide>
  </gazebo>

  <gazebo reference="link_Rbtm_roll2_1">
    <material>Gazebo/White</material>
        <gravity>1</gravity>
        <kp>1e10</kp>
        <kd>1e10</kd>
        <mu1>2000.0</mu1>
        <mu2>2000.0</mu2>
        <fdir1>0 0 1</fdir1>
        <maxVel>1.0</maxVel>
        <minDepth>0.001</minDepth>
    <selfCollide>true</selfCollide>
  </gazebo>

  <gazebo reference="link_Rbtm_pitch_1">
    <material>Gazebo/Grey</material>
        <gravity>1</gravity>
        <kp>1e10</kp>
        <kd>1e10</kd>
        <mu1>2000.0</mu1>
        <mu2>2000.0</mu2>
        <fdir1>0 0 1</fdir1>
        <maxVel>1.0</maxVel>
        <minDepth>0.001</minDepth>
    <selfCollide>true</selfCollide>
  </gazebo>

  <gazebo reference="link_Rbtm_roll1_1">
    <material>Gazebo/Grey</material>
        <gravity>1</gravity>
        <kp>1e10</kp>
        <kd>1e10</kd>
        <mu1>2000.0</mu1>
        <mu2>2000.0</mu2>
        <fdir1>0 0 1</fdir1>
        <maxVel>1.0</maxVel>
        <minDepth>0.001</minDepth>
    <selfCollide>true</selfCollide>
  </gazebo>

  <link name="base_link">
    <inertial>
      <origin xyz="0.00792150552871263 0.004962055813034319 0.04887561199610228" rpy="0 0 0"/>
      <mass value="4.522182710031079"/>
      <inertia ixx="0.027915" iyy="0.052072" izz="0.073658" ixy="-0.000771" iyz="-3.2e-05" ixz="-0.001061"/>
    </inertial>
    <visual>
      <origin xyz="0 0 0" rpy="0 0 0"/>
      <geometry>
        <mesh filename="file://$(find manta_v2_description)/meshes/base_link.dae" scale="0.001 0.001 0.001"/>
      </geometry>
      <material name="grey"/>
    </visual>
    <collision>
      <origin xyz="0 0 0" rpy="0 0 0"/>
      <geometry>
        <mesh filename="file://$(find manta_v2_description)/meshes/base_link.dae" scale="0.001 0.001 0.001"/>
      </geometry>
    </collision>
  </link>

  <link name="link_ballast_1">
    <inertial>
      <origin xyz="-0.07960543278014993 -0.00695335561539551 0.030294218443180032" rpy="0 0 0"/>
      <mass value="1.30386733013372"/>
      <inertia ixx="0.004658" iyy="0.013805" izz="0.017453" ixy="8.3e-05" iyz="3e-06" ixz="2.1e-05"/>
    </inertial>
    <visual>
      <origin xyz="-0.072432 -0.009863 -0.099806" rpy="0 0 0"/>
      <geometry>
        <mesh filename="file://$(find manta_v2_description)/meshes/link_ballast_1.stl" scale="0.001 0.001 0.001"/>
      </geometry>
      <material name="silver"/>
    </visual>
    <collision>
      <origin xyz="-0.072432 -0.009863 -0.099806" rpy="0 0 0"/>
      <geometry>
        <mesh filename="file://$(find manta_v2_description)/meshes/link_ballast_1.stl" scale="0.001 0.001 0.001"/>
      </geometry>
    </collision>
  </link>

  <link name="link_rs_camera_1">
    <inertial>
      <origin xyz="0.011287718132334673 -0.042841209422057845 -2.873946484678591e-05" rpy="0 0 0"/>
      <mass value="0.036593258350556095"/>
      <inertia ixx="2.4e-05" iyy="4e-06" izz="2.4e-05" ixy="0.0" iyz="0.0" ixz="0.0"/>
    </inertial>
    <visual>
      <origin xyz="-0.197763 0.007669 -0.055256" rpy="0 0 0"/>
      <geometry>
        <mesh filename="file://$(find manta_v2_description)/meshes/link_rs_camera_1.stl" scale="0.001 0.001 0.001"/>
      </geometry>
      <material name="grey"/>
    </visual>
    <collision>
      <origin xyz="-0.197763 0.007669 -0.055256" rpy="0 0 0"/>
      <geometry>
        <mesh filename="file://$(find manta_v2_description)/meshes/link_rs_camera_1.stl" scale="0.001 0.001 0.001"/>
      </geometry>
    </collision>
  </link>

  <link name="link_head_1">
    <inertial>
      <origin xyz="0.04544036564455914 -0.06561980433787044 -0.004846636476143737" rpy="0 0 0"/>
      <mass value="0.9360255744141788"/>
      <inertia ixx="0.007686" iyy="0.001338" izz="0.007639" ixy="6e-06" iyz="-4.3e-05" ixz="0.000284"/>
    </inertial>
    <visual>
      <origin xyz="-0.169458 -0.068853 -0.050106" rpy="0 0 0"/>
      <geometry>
        <mesh filename="file://$(find manta_v2_description)/meshes/link_head_1.dae" scale="0.001 0.001 0.001"/>
      </geometry>
      <material name="grey"/>
    </visual>
    <collision>
      <origin xyz="-0.169458 -0.068853 -0.050106" rpy="0 0 0"/>
      <geometry>
        <mesh filename="file://$(find manta_v2_description)/meshes/link_head_1.dae" scale="0.001 0.001 0.001"/>
      </geometry>
    </collision>
  </link>

  <link name="link_Ltop_end_1">
    <inertial>
      <origin xyz="-0.011627942814472339 0.03627732534090844 -1.607697173128253e-05" rpy="0 0 0"/>
      <mass value="0.015323903713098518"/>
      <inertia ixx="5e-06" iyy="2e-06" izz="6e-06" ixy="2e-06" iyz="-0.0" ixz="0.0"/>
    </inertial>
    <visual>
      <origin xyz="0.035713 -0.445596 -0.050144" rpy="0 0 0"/>
      <geometry>
        <mesh filename="file://$(find manta_v2_description)/meshes/link_Ltop_end_1.stl" scale="0.001 0.001 0.001"/>
      </geometry>
      <material name="silver"/>
    </visual>
    <collision>
      <origin xyz="0.035713 -0.445596 -0.050144" rpy="0 0 0"/>
      <geometry>
        <mesh filename="file://$(find manta_v2_description)/meshes/link_Ltop_end_1.stl" scale="0.001 0.001 0.001"/>
      </geometry>
    </collision>
  </link>

  <link name="link_Ltop_roll2_1">
    <inertial>
      <origin xyz="-0.05064002414664911 0.07234721149249257 0.0001474130852572239" rpy="0 0 0"/>
      <mass value="0.14280985397630655"/>
      <inertia ixx="0.000272" iyy="0.000139" izz="0.000404" ixy="0.000151" iyz="0.0" ixz="-0.0"/>
    </inertial>
    <visual>
      <origin xyz="-0.068925 -0.304483 -0.050056" rpy="0 0 0"/>
      <geometry>
        <mesh filename="file://$(find manta_v2_description)/meshes/link_Ltop_roll2_1.stl" scale="0.001 0.001 0.001"/>
      </geometry>
      <material name="silver"/>
    </visual>
    <collision>
      <origin xyz="-0.068925 -0.304483 -0.050056" rpy="0 0 0"/>
      <geometry>
        <mesh filename="file://$(find manta_v2_description)/meshes/link_Ltop_roll2_1.stl" scale="0.001 0.001 0.001"/>
      </geometry>
    </collision>
  </link>

  <link name="link_Ltop_pitch_1">
    <inertial>
      <origin xyz="-0.0036035622757067676 0.046650503054064874 -9.903652576324223e-05" rpy="0 0 0"/>
      <mass value="0.17822306140653552"/>
      <inertia ixx="0.000123" iyy="0.000149" izz="0.000254" ixy="5.1e-05" iyz="-0.0" ixz="0.0"/>
    </inertial>
    <visual>
      <origin xyz="-0.077217 -0.217765 -0.050056" rpy="0 0 0"/>
      <geometry>
        <mesh filename="file://$(find manta_v2_description)/meshes/link_Ltop_pitch_1.stl" scale="0.001 0.001 0.001"/>
      </geometry>
      <material name="grey"/>
    </visual>
    <collision>
      <origin xyz="-0.077217 -0.217765 -0.050056" rpy="0 0 0"/>
      <geometry>
        <mesh filename="file://$(find manta_v2_description)/meshes/link_Ltop_pitch_1.stl" scale="0.001 0.001 0.001"/>
      </geometry>
    </collision>
  </link>

  <link name="link_Ltop_roll1_1">
    <inertial>
      <origin xyz="-0.03076571133852378 0.038562518219365516 0.00018122130753521482" rpy="0 0 0"/>
      <mass value="0.19434161563031094"/>
      <inertia ixx="0.000104" iyy="0.000241" izz="0.000317" ixy="1e-06" iyz="0.0" ixz="-0.0"/>
    </inertial>
    <visual>
      <origin xyz="-0.137421 -0.145942 -0.049756" rpy="0 0 0"/>
      <geometry>
        <mesh filename="file://$(find manta_v2_description)/meshes/link_Ltop_roll1_1.stl" scale="0.001 0.001 0.001"/>
      </geometry>
      <material name="grey"/>
    </visual>
    <collision>
      <origin xyz="-0.137421 -0.145942 -0.049756" rpy="0 0 0"/>
      <geometry>
        <mesh filename="file://$(find manta_v2_description)/meshes/link_Ltop_roll1_1.stl" scale="0.001 0.001 0.001"/>
      </geometry>
    </collision>
  </link>

  <link name="link_Lmid_end_1">
    <inertial>
      <origin xyz="0.002224623757043964 0.025441564496730185 -1.3114325672032578e-05" rpy="0 0 0"/>
      <mass value="0.007441954067322181"/>
      <inertia ixx="1e-06" iyy="1e-06" izz="2e-06" ixy="0.0" iyz="-0.0" ixz="0.0"/>
    </inertial>
    <visual>
      <origin xyz="0.071879 -0.452632 -0.050739" rpy="0 0 0"/>
      <geometry>
        <mesh filename="file://$(find manta_v2_description)/meshes/link_Lmid_end_1.stl" scale="0.001 0.001 0.001"/>
      </geometry>
      <material name="silver"/>
    </visual>
    <collision>
      <origin xyz="0.071879 -0.452632 -0.050739" rpy="0 0 0"/>
      <geometry>
        <mesh filename="file://$(find manta_v2_description)/meshes/link_Lmid_end_1.stl" scale="0.001 0.001 0.001"/>
      </geometry>
    </collision>
  </link>

  <link name="link_Lmid_roll2_1">
    <inertial>
      <origin xyz="-0.032927504762074844 0.07395305292299315 7.673978602938669e-05" rpy="0 0 0"/>
      <mass value="0.12070455894406873"/>
      <inertia ixx="0.000249" iyy="5.6e-05" izz="0.0003" ixy="7.1e-05" iyz="1e-06" ixz="-0.0"/>
    </inertial>
    <visual>
      <origin xyz="0.002795 -0.288978 -0.050754" rpy="0 0 0"/>
      <geometry>
        <mesh filename="file://$(find manta_v2_description)/meshes/link_Lmid_roll2_1.stl" scale="0.001 0.001 0.001"/>
      </geometry>
      <material name="silver"/>
    </visual>
    <collision>
      <origin xyz="0.002795 -0.288978 -0.050754" rpy="0 0 0"/>
      <geometry>
        <mesh filename="file://$(find manta_v2_description)/meshes/link_Lmid_roll2_1.stl" scale="0.001 0.001 0.001"/>
      </geometry>
    </collision>
  </link>

  <link name="link_Lmid_pitch_1">
    <inertial>
      <origin xyz="-0.013129429293904659 0.04375334655807747 8.214047001718627e-05" rpy="0 0 0"/>
      <mass value="0.15932454552190675"/>
      <inertia ixx="0.000118" iyy="9.6e-05" izz="0.000199" ixy="2.2e-05" iyz="-0.0" ixz="0.0"/>
    </inertial>
    <visual>
      <origin xyz="-0.002525 -0.204299 -0.050555" rpy="0 0 0"/>
      <geometry>
        <mesh filename="file://$(find manta_v2_description)/meshes/link_Lmid_pitch_1.stl" scale="0.001 0.001 0.001"/>
      </geometry>
      <material name="grey"/>
    </visual>
    <collision>
      <origin xyz="-0.002525 -0.204299 -0.050555" rpy="0 0 0"/>
      <geometry>
        <mesh filename="file://$(find manta_v2_description)/meshes/link_Lmid_pitch_1.stl" scale="0.001 0.001 0.001"/>
      </geometry>
    </collision>
  </link>

  <link name="link_Lmid_roll1_1">
    <inertial>
      <origin xyz="-0.04081539162142128 0.040080323635497433 0.0002592852203608456" rpy="0 0 0"/>
      <mass value="0.15518282022005683"/>
      <inertia ixx="7.9e-05" iyy="0.00013" izz="0.000187" ixy="-2.4e-05" iyz="0.0" ixz="-0.0"/>
    </inertial>
    <visual>
      <origin xyz="-0.042544 -0.129109 -0.050256" rpy="0 0 0"/>
      <geometry>
        <mesh filename="file://$(find manta_v2_description)/meshes/link_Lmid_roll1_1.stl" scale="0.001 0.001 0.001"/>
      </geometry>
      <material name="grey"/>
    </visual>
    <collision>
      <origin xyz="-0.042544 -0.129109 -0.050256" rpy="0 0 0"/>
      <geometry>
        <mesh filename="file://$(find manta_v2_description)/meshes/link_Lmid_roll1_1.stl" scale="0.001 0.001 0.001"/>
      </geometry>
    </collision>
  </link>

  <link name="link_Lbtm_end_1">
    <inertial>
      <origin xyz="0.00617745540106622 0.033663127168304385 -2.8032488534904254e-05" rpy="0 0 0"/>
      <mass value="0.017926653939189092"/>
      <inertia ixx="7e-06" iyy="1e-06" izz="8e-06" ixy="-0.0" iyz="-0.0" ixz="0.0"/>
    </inertial>
    <visual>
      <origin xyz="0.100506 -0.435125 -0.050144" rpy="0 0 0"/>
      <geometry>
        <mesh filename="file://$(find manta_v2_description)/meshes/link_Lbtm_end_1.stl" scale="0.001 0.001 0.001"/>
      </geometry>
      <material name="silver"/>
    </visual>
    <collision>
      <origin xyz="0.100506 -0.435125 -0.050144" rpy="0 0 0"/>
      <geometry>
        <mesh filename="file://$(find manta_v2_description)/meshes/link_Lbtm_end_1.stl" scale="0.001 0.001 0.001"/>
      </geometry>
    </collision>
  </link>

  <link name="link_Lbtm_roll2_1">
    <inertial>
      <origin xyz="-0.02295809842777921 0.07518849372220049 0.00015303621803120643" rpy="0 0 0"/>
      <mass value="0.1005290606904074"/>
      <inertia ixx="0.000216" iyy="2.2e-05" izz="0.000233" ixy="-6e-06" iyz="0.0" ixz="-0.0"/>
    </inertial>
    <visual>
      <origin xyz="0.067218 -0.280707 -0.050056" rpy="0 0 0"/>
      <geometry>
        <mesh filename="file://$(find manta_v2_description)/meshes/link_Lbtm_roll2_1.stl" scale="0.001 0.001 0.001"/>
      </geometry>
      <material name="silver"/>
    </visual>
    <collision>
      <origin xyz="0.067218 -0.280707 -0.050056" rpy="0 0 0"/>
      <geometry>
        <mesh filename="file://$(find manta_v2_description)/meshes/link_Lbtm_roll2_1.stl" scale="0.001 0.001 0.001"/>
      </geometry>
    </collision>
  </link>

  <link name="link_Lbtm_pitch_1">
    <inertial>
      <origin xyz="0.002910896656933032 0.04810943466764439 -0.00010578850921785093" rpy="0 0 0"/>
      <mass value="0.16585300361439087"/>
      <inertia ixx="0.000142" iyy="8.6e-05" izz="0.000213" ixy="-1.4e-05" iyz="-0.0" ixz="-0.0"/>
    </inertial>
    <visual>
      <origin xyz="0.094083 -0.188123 -0.050056" rpy="0 0 0"/>
      <geometry>
        <mesh filename="file://$(find manta_v2_description)/meshes/link_Lbtm_pitch_1.stl" scale="0.001 0.001 0.001"/>
      </geometry>
      <material name="grey"/>
    </visual>
    <collision>
      <origin xyz="0.094083 -0.188123 -0.050056" rpy="0 0 0"/>
      <geometry>
        <mesh filename="file://$(find manta_v2_description)/meshes/link_Lbtm_pitch_1.stl" scale="0.001 0.001 0.001"/>
      </geometry>
    </collision>
  </link>

  <link name="link_Lbtm_roll1_1">
    <inertial>
      <origin xyz="-0.045037793021241355 0.03564712654180677 0.00020374800322018466" rpy="0 0 0"/>
      <mass value="0.1804116009640628"/>
      <inertia ixx="0.00013" iyy="0.000185" izz="0.000286" ixy="-7.5e-05" iyz="0.0" ixz="-0.0"/>
    </inertial>
    <visual>
      <origin xyz="0.054262 -0.112901 -0.049956" rpy="0 0 0"/>
      <geometry>
        <mesh filename="file://$(find manta_v2_description)/meshes/link_Lbtm_roll1_1.stl" scale="0.001 0.001 0.001"/>
      </geometry>
      <material name="grey"/>
    </visual>
    <collision>
      <origin xyz="0.054262 -0.112901 -0.049956" rpy="0 0 0"/>
      <geometry>
        <mesh filename="file://$(find manta_v2_description)/meshes/link_Lbtm_roll1_1.stl" scale="0.001 0.001 0.001"/>
      </geometry>
    </collision>
  </link>

  <link name="link_Rtop_end_1">
    <inertial>
      <origin xyz="-0.01232252117640463 -0.036044053813726495 -1.589328587881661e-05" rpy="0 0 0"/>
      <mass value="0.015323373069045321"/>
      <inertia ixx="5e-06" iyy="2e-06" izz="6e-06" ixy="-2e-06" iyz="0.0" ixz="0.0"/>
    </inertial>
    <visual>
      <origin xyz="0.043804 0.437756 -0.050768" rpy="0 0 0"/>
      <geometry>
        <mesh filename="file://$(find manta_v2_description)/meshes/link_Rtop_end_1.stl" scale="0.001 0.001 0.001"/>
      </geometry>
      <material name="silver"/>
    </visual>
    <collision>
      <origin xyz="0.043804 0.437756 -0.050768" rpy="0 0 0"/>
      <geometry>
        <mesh filename="file://$(find manta_v2_description)/meshes/link_Rtop_end_1.stl" scale="0.001 0.001 0.001"/>
      </geometry>
    </collision>
  </link>

  <link name="link_Rtop_roll2_1">
    <inertial>
      <origin xyz="-0.05202803534724799 -0.07149746775469151 0.0002429158889384747" rpy="0 0 0"/>
      <mass value="0.14179132315104725"/>
      <inertia ixx="0.000265" iyy="0.000143" izz="0.000402" ixy="-0.000153" iyz="-0.0" ixz="-0.0"/>
    </inertial>
    <visual>
      <origin xyz="-0.063395 0.298578 -0.050656" rpy="0 0 0"/>
      <geometry>
        <mesh filename="file://$(find manta_v2_description)/meshes/link_Rtop_roll2_1.stl" scale="0.001 0.001 0.001"/>
      </geometry>
      <material name="silver"/>
    </visual>
    <collision>
      <origin xyz="-0.063395 0.298578 -0.050656" rpy="0 0 0"/>
      <geometry>
        <mesh filename="file://$(find manta_v2_description)/meshes/link_Rtop_roll2_1.stl" scale="0.001 0.001 0.001"/>
      </geometry>
    </collision>
  </link>

  <link name="link_Rtop_pitch_1">
    <inertial>
      <origin xyz="-0.0044547609430659885 -0.04657616250980609 -9.903653260546347e-05" rpy="0 0 0"/>
      <mass value="0.17822305765306265"/>
      <inertia ixx="0.000121" iyy="0.000151" izz="0.000254" ixy="-5e-05" iyz="0.0" ixz="0.0"/>
    </inertial>
    <visual>
      <origin xyz="-0.073269 0.212027 -0.050656" rpy="0 0 0"/>
      <geometry>
        <mesh filename="file://$(find manta_v2_description)/meshes/link_Rtop_pitch_1.stl" scale="0.001 0.001 0.001"/>
      </geometry>
      <material name="grey"/>
    </visual>
    <collision>
      <origin xyz="-0.073269 0.212027 -0.050656" rpy="0 0 0"/>
      <geometry>
        <mesh filename="file://$(find manta_v2_description)/meshes/link_Rtop_pitch_1.stl" scale="0.001 0.001 0.001"/>
      </geometry>
    </collision>
  </link>

  <link name="link_Rtop_roll1_1">
    <inertial>
      <origin xyz="-0.03146452077802561 -0.03799411865425728 0.00018131737289966282" rpy="0 0 0"/>
      <mass value="0.19434194856212572"/>
      <inertia ixx="0.000104" iyy="0.000241" izz="0.000317" ixy="1e-06" iyz="-0.0" ixz="-0.0"/>
    </inertial>
    <visual>
      <origin xyz="-0.134775 0.141315 -0.050356" rpy="0 0 0"/>
      <geometry>
        <mesh filename="file://$(find manta_v2_description)/meshes/link_Rtop_roll1_1.stl" scale="0.001 0.001 0.001"/>
      </geometry>
      <material name="grey"/>
    </visual>
    <collision>
      <origin xyz="-0.134775 0.141315 -0.050356" rpy="0 0 0"/>
      <geometry>
        <mesh filename="file://$(find manta_v2_description)/meshes/link_Rtop_roll1_1.stl" scale="0.001 0.001 0.001"/>
      </geometry>
    </collision>
  </link>

  <link name="link_Rmid_end_1">
    <inertial>
      <origin xyz="0.00176572112122865 -0.025419562867362633 0.0017123569232994768" rpy="0 0 0"/>
      <mass value="0.007441953757708133"/>
      <inertia ixx="1e-06" iyy="1e-06" izz="2e-06" ixy="-0.0" iyz="0.0" ixz="0.0"/>
    </inertial>
    <visual>
      <origin xyz="0.079726 0.445452 -0.062419" rpy="0 0 0"/>
      <geometry>
        <mesh filename="file://$(find manta_v2_description)/meshes/link_Rmid_end_1.stl" scale="0.001 0.001 0.001"/>
      </geometry>
      <material name="silver"/>
    </visual>
    <collision>
      <origin xyz="0.079726 0.445452 -0.062419" rpy="0 0 0"/>
      <geometry>
        <mesh filename="file://$(find manta_v2_description)/meshes/link_Rmid_end_1.stl" scale="0.001 0.001 0.001"/>
      </geometry>
    </collision>
  </link>

  <link name="link_Rmid_roll2_1">
    <inertial>
      <origin xyz="-0.034250191736584376 -0.07313875746625575 0.005567305027854477" rpy="0 0 0"/>
      <mass value="0.12070445308044621"/>
      <inertia ixx="0.000247" iyy="6e-05" izz="0.000299" ixy="-7.4e-05" iyz="1.7e-05" ixz="5e-06"/>
    </inertial>
    <visual>
      <origin xyz="0.007712 0.283514 -0.050356" rpy="0 0 0"/>
      <geometry>
        <mesh filename="file://$(find manta_v2_description)/meshes/link_Rmid_roll2_1.stl" scale="0.001 0.001 0.001"/>
      </geometry>
      <material name="silver"/>
    </visual>
    <collision>
      <origin xyz="0.007712 0.283514 -0.050356" rpy="0 0 0"/>
      <geometry>
        <mesh filename="file://$(find manta_v2_description)/meshes/link_Rmid_roll2_1.stl" scale="0.001 0.001 0.001"/>
      </geometry>
    </collision>
  </link>

  <link name="link_Rmid_pitch_1">
    <inertial>
      <origin xyz="-0.014180285553615118 -0.0451779529640845 8.132967962298093e-05" rpy="0 0 0"/>
      <mass value="0.1600965983539415"/>
      <inertia ixx="0.000119" iyy="9.7e-05" izz="0.0002" ixy="-2.2e-05" iyz="0.0" ixz="0.0"/>
    </inertial>
    <visual>
      <origin xyz="0.000538 0.19737 -0.050156" rpy="0 0 0"/>
      <geometry>
        <mesh filename="file://$(find manta_v2_description)/meshes/link_Rmid_pitch_1.stl" scale="0.001 0.001 0.001"/>
      </geometry>
      <material name="grey"/>
    </visual>
    <collision>
      <origin xyz="0.000538 0.19737 -0.050156" rpy="0 0 0"/>
      <geometry>
        <mesh filename="file://$(find manta_v2_description)/meshes/link_Rmid_pitch_1.stl" scale="0.001 0.001 0.001"/>
      </geometry>
    </collision>
  </link>

  <link name="link_Rmid_roll1_1">
    <inertial>
      <origin xyz="-0.04143098632374882 -0.039313325247788855 0.00021364819700269572" rpy="0 0 0"/>
      <mass value="0.15485223449650745"/>
      <inertia ixx="8e-05" iyy="0.000129" izz="0.000186" ixy="2.5e-05" iyz="-0.0" ixz="-0.0"/>
    </inertial>
    <visual>
      <origin xyz="-0.040221 0.122812 -0.050056" rpy="0 0 0"/>
      <geometry>
        <mesh filename="file://$(find manta_v2_description)/meshes/link_Rmid_roll1_1.stl" scale="0.001 0.001 0.001"/>
      </geometry>
      <material name="grey"/>
    </visual>
    <collision>
      <origin xyz="-0.040221 0.122812 -0.050056" rpy="0 0 0"/>
      <geometry>
        <mesh filename="file://$(find manta_v2_description)/meshes/link_Rmid_roll1_1.stl" scale="0.001 0.001 0.001"/>
      </geometry>
    </collision>
  </link>

  <link name="link_Rbtm_end_1">
    <inertial>
      <origin xyz="0.005555802752706798 -0.03377102305595908 -2.8438982940102997e-05" rpy="0 0 0"/>
      <mass value="0.017926640731321712"/>
      <inertia ixx="7e-06" iyy="1e-06" izz="8e-06" ixy="0.0" iyz="0.0" ixz="0.0"/>
    </inertial>
    <visual>
      <origin xyz="0.108026 0.426064 -0.050268" rpy="0 0 0"/>
      <geometry>
        <mesh filename="file://$(find manta_v2_description)/meshes/link_Rbtm_end_1.stl" scale="0.001 0.001 0.001"/>
      </geometry>
      <material name="silver"/>
    </visual>
    <collision>
      <origin xyz="0.108026 0.426064 -0.050268" rpy="0 0 0"/>
      <geometry>
        <mesh filename="file://$(find manta_v2_description)/meshes/link_Rbtm_end_1.stl" scale="0.001 0.001 0.001"/>
      </geometry>
    </collision>
  </link>

  <link name="link_Rbtm_roll2_1">
    <inertial>
      <origin xyz="-0.02431579788979281 -0.07489498194146449 0.00022099223531780315" rpy="0 0 0"/>
      <mass value="0.10007820890955299"/>
      <inertia ixx="0.000215" iyy="2.2e-05" izz="0.000232" ixy="2e-06" iyz="-1e-06" ixz="-0.0"/>
    </inertial>
    <visual>
      <origin xyz="0.071896 0.272285 -0.050156" rpy="0 0 0"/>
      <geometry>
        <mesh filename="file://$(find manta_v2_description)/meshes/link_Rbtm_roll2_1.stl" scale="0.001 0.001 0.001"/>
      </geometry>
      <material name="silver"/>
    </visual>
    <collision>
      <origin xyz="0.071896 0.272285 -0.050156" rpy="0 0 0"/>
      <geometry>
        <mesh filename="file://$(find manta_v2_description)/meshes/link_Rbtm_roll2_1.stl" scale="0.001 0.001 0.001"/>
      </geometry>
    </collision>
  </link>

  <link name="link_Rbtm_pitch_1">
    <inertial>
      <origin xyz="0.0020239667462722127 -0.048155084895369016 -0.000149657853420547" rpy="0 0 0"/>
      <mass value="0.16585300431074718"/>
      <inertia ixx="0.000143" iyy="8.6e-05" izz="0.000213" ixy="1.2e-05" iyz="-0.0" ixz="-0.0"/>
    </inertial>
    <visual>
      <origin xyz="0.09705 0.179222 -0.050356" rpy="0 0 0"/>
      <geometry>
        <mesh filename="file://$(find manta_v2_description)/meshes/link_Rbtm_pitch_1.stl" scale="0.001 0.001 0.001"/>
      </geometry>
      <material name="grey"/>
    </visual>
    <collision>
      <origin xyz="0.09705 0.179222 -0.050356" rpy="0 0 0"/>
      <geometry>
        <mesh filename="file://$(find manta_v2_description)/meshes/link_Rbtm_pitch_1.stl" scale="0.001 0.001 0.001"/>
      </geometry>
    </collision>
  </link>

  <link name="link_Rbtm_roll1_1">
    <inertial>
      <origin xyz="-0.04527451140152236 -0.03473768479405631 0.00020379463598722836" rpy="0 0 0"/>
      <mass value="0.1804094931462181"/>
      <inertia ixx="0.000133" iyy="0.000182" izz="0.000286" ixy="7.6e-05" iyz="-0.0" ixz="-0.0"/>
    </inertial>
    <visual>
      <origin xyz="0.056269 0.104821 -0.050256" rpy="0 0 0"/>
      <geometry>
        <mesh filename="file://$(find manta_v2_description)/meshes/link_Rbtm_roll1_1.stl" scale="0.001 0.001 0.001"/>
      </geometry>
      <material name="grey"/>
    </visual>
    <collision>
      <origin xyz="0.056269 0.104821 -0.050256" rpy="0 0 0"/>
      <geometry>
        <mesh filename="file://$(find manta_v2_description)/meshes/link_Rbtm_roll1_1.stl" scale="0.001 0.001 0.001"/>
      </geometry>
    </collision>
  </link>

  <!-- <link name="world"/>

  <link name="world_stand">
    <inertial>
      <mass value="1.0" />
      <origin xyz="0 0 0" />
    <inertia  ixx="1.0" ixy="0.0"  ixz="0.0"  iyy="100.0"  iyz="0.0"  izz="1.0"/>
    </inertial>
    <visual>
      <origin xyz="0 0 0" rpy="0 0 0" />
      <geometry name="my_box_visual_geom">
        <box size="0.3 0.2 0.3" />
      </geometry>
    </visual>
    <collision>
      <origin xyz="0 0 0" rpy="0 0 0 " />
      <geometry name="my_box_collision_geom">
        <box size="0.3 0.2 0.3" />
      </geometry>
    </collision>
  </link>

  <joint name="world_to_stand" type="fixed">
    <origin rpy="0 0 0" xyz="0 0 0.15"/>
    <parent link="world"/>
    <child link="world_stand"/>
    <dynamics damping="0.1" friction="10000000"/>
  </joint>

  <joint name="stand_to_base" type="fixed">
    <origin rpy="0 0 0" xyz="0 0 0.15"/>
    <parent link="world_stand"/>
    <child link="base_link"/>
    <dynamics damping="100000" friction="100000"/>
  </joint> -->

  <joint name="con_link_ballast" type="fixed">
    <origin xyz="0.072432 0.009863 0.099806" rpy="0 0 0"/>
    <parent link="base_link"/>
    <child link="link_ballast_1"/>
  </joint>

  <joint name="con_link_rs_camera" type="fixed">
    <origin xyz="0.028305 -0.076522 0.00515" rpy="0 0 0"/>
    <parent link="link_head_1"/>
    <child link="link_rs_camera_1"/>
  </joint>

  <joint name="rev_link_head" type="revolute">
    <origin xyz="0.169458 0.068853 0.050106" rpy="0 0 0"/>
    <parent link="base_link"/>
    <child link="link_head_1"/>
    <axis xyz="0.00922 0.999957 0.0"/>
    <limit upper="0.349066" lower="-0.349066" effort="100" velocity="100"/>
    <dynamics damping="0.1" friction="0.0"/>
  </joint>

  <joint name="con_link_Ltop_end" type="fixed">
    <origin xyz="-0.104638 0.141113 8.8e-05" rpy="0 0 0"/>
    <parent link="link_Ltop_roll2_1"/>
    <child link="link_Ltop_end_1"/>
  </joint>

  <joint name="rev_link_Ltop_roll2" type="revolute">
    <origin xyz="-0.008292 0.086718 0.0" rpy="0 0 0"/>
    <parent link="link_Ltop_pitch_1"/>
    <child link="link_Ltop_roll2_1"/>
    <axis xyz="-0.986372 -0.164529 -0.0"/>
    <limit upper="0.698132" lower="-0.698132" effort="100" velocity="100"/>
    <dynamics damping="0.1" friction="0.0"/>
  </joint>

  <joint name="rev_link_Ltop_pitch" type="revolute">
    <origin xyz="-0.060204 0.071823 0.0003" rpy="0 0 0"/>
    <parent link="link_Ltop_roll1_1"/>
    <child link="link_Ltop_pitch_1"/>
    <axis xyz="0.164529 -0.986372 -0.0"/>
    <limit upper="0.698132" lower="-0.698132" effort="100" velocity="100"/>
    <dynamics damping="0.1" friction="0.0"/>
  </joint>

  <joint name="rev_link_Ltop_roll1" type="revolute">
    <origin xyz="0.137421 0.145942 0.049756" rpy="0 0 0"/>
    <parent link="base_link"/>
    <child link="link_Ltop_roll1_1"/>
    <axis xyz="0.986372 0.164529 0.0"/>
    <limit upper="0.523599" lower="-0.523599" effort="100" velocity="100"/>
    <dynamics damping="0.1" friction="0.0"/>
  </joint>

  <joint name="con_link_Lmid_end" type="fixed">
    <origin xyz="-0.069084 0.163654 -1.5e-05" rpy="0 0 0"/>
    <parent link="link_Lmid_roll2_1"/>
    <child link="link_Lmid_end_1"/>
  </joint>

  <joint name="rev_link_Lmid_roll2" type="revolute">
    <origin xyz="-0.00532 0.084679 0.000199" rpy="0 0 0"/>
    <parent link="link_Lmid_pitch_1"/>
    <child link="link_Lmid_roll2_1"/>
    <axis xyz="-0.986367 -0.16456 -0.0"/>
    <limit upper="0.698132" lower="-0.698132" effort="100" velocity="100"/>
    <dynamics damping="0.1" friction="0.0"/>
  </joint>

  <joint name="rev_link_Lmid_pitch" type="revolute">
    <origin xyz="-0.040019 0.07519 0.000299" rpy="0 0 0"/>
    <parent link="link_Lmid_roll1_1"/>
    <child link="link_Lmid_pitch_1"/>
    <axis xyz="0.16456 -0.986367 1.3e-05"/>
    <limit upper="0.698132" lower="-0.698132" effort="100" velocity="100"/>
    <dynamics damping="0.1" friction="0.0"/>
  </joint>

  <joint name="rev_link_Lmid_roll1" type="revolute">
    <origin xyz="0.042544 0.129109 0.050256" rpy="0 0 0"/>
    <parent link="base_link"/>
    <child link="link_Lmid_roll1_1"/>
    <axis xyz="0.986367 0.16456 0.0"/>
    <limit upper="0.523599" lower="-0.523599" effort="100" velocity="100"/>
    <dynamics damping="0.1" friction="0.0"/>
  </joint>

  <joint name="con_link_Lbtm_end" type="fixed">
    <origin xyz="-0.033288 0.154418 8.8e-05" rpy="0 0 0"/>
    <parent link="link_Lbtm_roll2_1"/>
    <child link="link_Lbtm_end_1"/>
  </joint>

  <joint name="rev_link_Lbtm_roll2" type="revolute">
    <origin xyz="0.026865 0.092584 0.0" rpy="0 0 0"/>
    <parent link="link_Lbtm_pitch_1"/>
    <child link="link_Lbtm_roll2_1"/>
    <axis xyz="-0.986367 -0.16456 -0.0"/>
    <limit upper="0.698132" lower="-0.698132" effort="100" velocity="100"/>
    <dynamics damping="0.1" friction="0.0"/>
  </joint>

  <joint name="rev_link_Lbtm_pitch" type="revolute">
    <origin xyz="-0.039821 0.075222 0.0001" rpy="0 0 0"/>
    <parent link="link_Lbtm_roll1_1"/>
    <child link="link_Lbtm_pitch_1"/>
    <axis xyz="0.16456 -0.986367 -1e-06"/>
    <limit upper="0.698132" lower="-0.698132" effort="100" velocity="100"/>
    <dynamics damping="0.1" friction="0.0"/>
  </joint>

  <joint name="rev_link_Lbtm_roll1" type="revolute">
    <origin xyz="-0.054262 0.112901 0.049956" rpy="0 0 0"/>
    <parent link="base_link"/>
    <child link="link_Lbtm_roll1_1"/>
    <axis xyz="0.986367 0.16456 0.0"/>
    <limit upper="0.523599" lower="-0.523599" effort="100" velocity="100"/>
    <dynamics damping="0.1" friction="0.0"/>
  </joint>

  <joint name="con_link_Rtop_end" type="fixed">
    <origin xyz="-0.107199 -0.139178 0.000112" rpy="0 0 0"/>
    <parent link="link_Rtop_roll2_1"/>
    <child link="link_Rtop_end_1"/>
  </joint>

  <joint name="rev_link_Rtop_roll2" type="revolute">
    <origin xyz="-0.009874 -0.086551 0.0" rpy="0 0 0"/>
    <parent link="link_Rtop_pitch_1"/>
    <child link="link_Rtop_roll2_1"/>
    <axis xyz="-0.983202 0.182521 0.0"/>
    <limit upper="0.698132" lower="-0.698132" effort="100" velocity="100"/>
    <dynamics damping="0.1" friction="0.0"/>
  </joint>

  <joint name="rev_link_Rtop_pitch" type="revolute">
    <origin xyz="-0.061506 -0.070712 0.0003" rpy="0 0 0"/>
    <parent link="link_Rtop_roll1_1"/>
    <child link="link_Rtop_pitch_1"/>
    <axis xyz="0.182521 0.983202 0.0"/>
    <limit upper="0.698132" lower="-0.698132" effort="100" velocity="100"/>
    <dynamics damping="0.1" friction="0.0"/>
  </joint>

  <joint name="rev_link_Rtop_roll1" type="revolute">
    <origin xyz="0.134775 -0.141315 0.050356" rpy="0 0 0"/>
    <parent link="base_link"/>
    <child link="link_Rtop_roll1_1"/>
    <axis xyz="0.983202 -0.182521 -0.0"/>
    <limit upper="0.523599" lower="-0.523599" effort="100" velocity="100"/>
    <dynamics damping="0.1" friction="0.0"/>
  </joint>

  <joint name="con_link_Rmid_end" type="fixed">
    <origin xyz="-0.072014 -0.161938 0.012063" rpy="0 0 0"/>
    <parent link="link_Rmid_roll2_1"/>
    <child link="link_Rmid_end_1"/>
  </joint>

  <joint name="rev_link_Rmid_roll2" type="revolute">
    <origin xyz="-0.007174 -0.086144 0.0002" rpy="0 0 0"/>
    <parent link="link_Rmid_pitch_1"/>
    <child link="link_Rmid_roll2_1"/>
    <axis xyz="-0.983165 0.182721 -5.7e-05"/>
    <limit upper="0.698132" lower="-0.698132" effort="100" velocity="100"/>
    <dynamics damping="0.1" friction="0.0"/>
  </joint>

  <joint name="rev_link_Rmid_pitch" type="revolute">
    <origin xyz="-0.040759 -0.074558 0.0001" rpy="0 0 0"/>
    <parent link="link_Rmid_roll1_1"/>
    <child link="link_Rmid_pitch_1"/>
    <axis xyz="0.182721 0.983165 0.0"/>
    <limit upper="0.698132" lower="-0.698132" effort="100" velocity="100"/>
    <dynamics damping="0.1" friction="0.0"/>
  </joint>

  <joint name="rev_link_Rmid_roll1" type="revolute">
    <origin xyz="0.040221 -0.122812 0.050056" rpy="0 0 0"/>
    <parent link="base_link"/>
    <child link="link_Rmid_roll1_1"/>
    <axis xyz="0.983165 -0.182721 -0.0"/>
    <limit upper="0.523599" lower="-0.523599" effort="100" velocity="100"/>
    <dynamics damping="0.1" friction="0.0"/>
  </joint>

  <joint name="con_link_Rbtm_end" type="fixed">
    <origin xyz="-0.03613 -0.153779 0.000112" rpy="0 0 0"/>
    <parent link="link_Rbtm_roll2_1"/>
    <child link="link_Rbtm_end_1"/>
  </joint>

  <joint name="rev_link_Rbtm_roll2" type="revolute">
    <origin xyz="0.025154 -0.093063 -0.0002" rpy="0 0 0"/>
    <parent link="link_Rbtm_pitch_1"/>
    <child link="link_Rbtm_roll2_1"/>
    <axis xyz="-0.983165 0.182721 0.0"/>
    <limit upper="0.698132" lower="-0.698132" effort="100" velocity="100"/>
    <dynamics damping="0.1" friction="0.0"/>
  </joint>

  <joint name="rev_link_Rbtm_pitch" type="revolute">
    <origin xyz="-0.040781 -0.074401 0.0001" rpy="0 0 0"/>
    <parent link="link_Rbtm_roll1_1"/>
    <child link="link_Rbtm_pitch_1"/>
    <axis xyz="0.182721 0.983165 0.0"/>
    <limit upper="0.698132" lower="-0.698132" effort="100" velocity="100"/>
    <dynamics damping="0.1" friction="0.0"/>
  </joint>

  <joint name="rev_link_Rbtm_roll1" type="revolute">
    <origin xyz="-0.056269 -0.104821 0.050256" rpy="0 0 0"/>
    <parent link="base_link"/>
    <child link="link_Rbtm_roll1_1"/>
    <axis xyz="0.983165 -0.182721 -0.0"/>
    <limit upper="0.523599" lower="-0.523599" effort="100" velocity="100"/>
    <dynamics damping="0.1" friction="0.0"/>
  </joint>

  <!-- ros2_control -->
  <ros2_control name="GazeboSystem" type="system">
    <hardware>
      <plugin>gazebo_ros2_control/GazeboSystem</plugin>
    </hardware>
      <!-- Rev Link R -->
    <joint name="rev_link_Rtop_roll1">
      <command_interface name="position">
        <param name="min">-0.5</param>
        <param name="max">0.5</param>
      </command_interface>
      <state_interface name="position"/>
      <state_interface name="velocity"/>
      <state_interface name="effort"/>
    </joint>
    <joint name="rev_link_Rtop_pitch">
      <command_interface name="position">
        <param name="min">-0.75</param>
        <param name="max">0.75</param>
      </command_interface>
      <state_interface name="position"/>
      <state_interface name="velocity"/>
      <state_interface name="effort"/>
    </joint>
    <joint name="rev_link_Rtop_roll2">
      <command_interface name="position">
        <param name="min">-0.75</param>
        <param name="max">0.75</param>
      </command_interface>
      <state_interface name="position"/>
      <state_interface name="velocity"/>
      <state_interface name="effort"/>
    </joint>
    <joint name="rev_link_Rmid_roll1">
    <command_interface name="position">
        <param name="min">-0.5</param>
        <param name="max">0.5</param>
      </command_interface>
      <state_interface name="position"/>
      <state_interface name="velocity"/>
      <state_interface name="effort"/>
    </joint>
    <joint name="rev_link_Rmid_pitch">
      <command_interface name="position">
        <param name="min">-0.75</param>
        <param name="max">0.75</param>
      </command_interface>
      <state_interface name="position"/>
      <state_interface name="velocity"/>
      <state_interface name="effort"/>
    </joint>
    <joint name="rev_link_Rmid_roll2">
      <command_interface name="position">
        <param name="min">-0.75</param>
        <param name="max">0.75</param>
      </command_interface>
      <state_interface name="position"/>
      <state_interface name="velocity"/>
      <state_interface name="effort"/>
    </joint>
    <joint name="rev_link_Rbtm_roll1">
      <command_interface name="position">
        <param name="min">-0.5</param>
        <param name="max">0.5</param>
      </command_interface>
      <state_interface name="position"/>
      <state_interface name="velocity"/>
      <state_interface name="effort"/>
    </joint>
    <joint name="rev_link_Rbtm_pitch">
      <command_interface name="position">
        <param name="min">-0.75</param>
        <param name="max">0.75</param>
      </command_interface>
      <state_interface name="position"/>
      <state_interface name="velocity"/>
      <state_interface name="effort"/>
    </joint>
    <joint name="rev_link_Rbtm_roll2">
      <command_interface name="position">
        <param name="min">-0.75</param>
        <param name="max">0.75</param>
      </command_interface>
      <state_interface name="position"/>
      <state_interface name="velocity"/>
      <state_interface name="effort"/>
    </joint>

    <!-- Rev Link L -->
    <joint name="rev_link_Ltop_roll1">
      <command_interface name="position">
        <param name="min">-0.5</param>
        <param name="max">0.5</param>
      </command_interface>
      <state_interface name="position"/>
      <state_interface name="velocity"/>
      <state_interface name="effort"/>
    </joint>
    <joint name="rev_link_Ltop_pitch">
      <command_interface name="position">
        <param name="min">-0.75</param>
        <param name="max">0.75</param>
      </command_interface>
      <state_interface name="position"/>
      <state_interface name="velocity"/>
      <state_interface name="effort"/>
    </joint>
    <joint name="rev_link_Ltop_roll2">
      <command_interface name="position">
        <param name="min">-0.75</param>
        <param name="max">0.75</param>
      </command_interface>
      <state_interface name="position"/>
      <state_interface name="velocity"/>
      <state_interface name="effort"/>
    </joint>
    <joint name="rev_link_Lmid_roll1">
      <command_interface name="position">
        <param name="min">-0.5</param>
        <param name="max">0.5</param>
      </command_interface>
      <state_interface name="position"/>
      <state_interface name="velocity"/>
      <state_interface name="effort"/>
    </joint>
    <joint name="rev_link_Lmid_pitch">
      <command_interface name="position">
        <param name="min">-0.75</param>
        <param name="max">0.75</param>
      </command_interface>
      <state_interface name="position"/>
      <state_interface name="velocity"/>
      <state_interface name="effort"/>
    </joint>
    <joint name="rev_link_Lmid_roll2">
      <command_interface name="position">
        <param name="min">-0.75</param>
        <param name="max">0.75</param>
      </command_interface>
      <state_interface name="position"/>
      <state_interface name="velocity"/>
      <state_interface name="effort"/>
    </joint>
    <joint name="rev_link_Lbtm_roll1">
      <command_interface name="position">
        <param name="min">-0.5</param>
        <param name="max">0.5</param>
      </command_interface>
      <state_interface name="position"/>
      <state_interface name="velocity"/>
      <state_interface name="effort"/>
    </joint>
    <joint name="rev_link_Lbtm_pitch">
      <command_interface name="position">
        <param name="min">-0.75</param>
        <param name="max">0.75</param>
      </command_interface>
      <state_interface name="position"/>
      <state_interface name="velocity"/>
      <state_interface name="effort"/>
    </joint>
    <joint name="rev_link_Lbtm_roll2">
      <command_interface name="position">
        <param name="min">-0.75</param>
        <param name="max">0.75</param>
      </command_interface>
      <state_interface name="position"/>
      <state_interface name="velocity"/>
      <state_interface name="effort"/>
    </joint>
    
    <!-- Rev Link Head -->
    <joint name="rev_link_head">
      <command_interface name="position">
        <param name="min">-0.35</param>
        <param name="max">0.35</param>
      </command_interface>
      <state_interface name="position"/>
      <state_interface name="velocity"/>
    </joint>

  </ros2_control>
  <gazebo>
    <plugin filename="libgazebo_ros2_control.so" name="gazebo_ros2_control">
      <robot_param>robot_description</robot_param>
      <robot_param_node>robot_state_publisher</robot_param_node>
      <!-- <parameters>$(find manta_v2_gazebo_ros2_control)/config/manta_v2_moveit_controller.yaml</parameters> -->
      <parameters>$(find manta_v2_gazebo_ros2_control)/config/manta_v2_trajectory_controller.yaml</parameters>
    </plugin>
  </gazebo>

</robot>
