<?xml version="1.0" ?>
<robot name="naro">

    <gazebo>
        <plugin name="gazebo_ros_control" filename="libgazebo_ros_control.so">
        </plugin>
    </gazebo>

	<!-- * * * Link Definitions * * * -->
    <link name="base_link">
 	    <inertial>
            <origin xyz="0 0 0" rpy="0 0 0"/>
            <mass value="1.78605" />
            <inertia ixx="0.0005726" ixy="0.0" ixz="0.0" iyy="0.0005726" iyz="0.0" izz="0.0002704"/>
        </inertial>
        <collision>
            <origin rpy="0.0 0 0" xyz="0 0 0"/>
            <geometry>
                <mesh filename="package://naro_description/meshes/NaroBody_1_v2.dae"/>
            </geometry>
        </collision>
        <visual>
            <origin rpy="0.0 0 0" xyz="0 0 0"/>
            <geometry>
                <mesh filename="package://naro_description/meshes/NaroBody_1_v2.dae"/>
            </geometry>
        </visual>
	</link>

    <gazebo reference="base_link">
        <kp>1000000.0</kp>
        <kd>1000000.0</kd>
        <mu1>10.0</mu1>
        <mu2>10.0</mu2>
    </gazebo>

    <link name="NaroBody_2_link">
 	    <inertial>
            <origin xyz="0 0 0" rpy="0 0 0"/>
            <mass value="0.7680916" />
            <inertia ixx="0.000220439071667" ixy="0.0" ixz="0.0" iyy="0.000220439071667" iyz="0.0" izz="0.00026615281"/>
        </inertial>
        <collision>
            <origin xyz="0 0 0" rpy="0 0 0"/>
            <geometry>
                <mesh filename="package://naro_description/meshes/NaroBody_2_v2.dae"/>
            </geometry>
        </collision>
        <visual>
            <origin xyz="0 0 0" rpy="0 0 0"/>
            <geometry>
                <mesh filename="package://naro_description/meshes/NaroBody_2_v2.dae"/>
            </geometry>
        </visual>
	</link>
    <!-- This is for color and physical properties in Gazebo, color won't work with the material tag in gazebo
    only for URDF coloring -->
    <gazebo reference="NaroBody_2_link">
        <kp>1000000.0</kp>
        <kd>1000000.0</kd>
        <mu1>10.0</mu1>
        <mu2>10.0</mu2>
    </gazebo>

    <joint name="NaroBody_1_NaroBody_2_joint" type="revolute">
    	<parent link="base_link"/>
    	<child link="NaroBody_2_link"/>
        <origin xyz="0 0 0.015" rpy="0 0 0"/>
        <limit lower="-0.2" upper="0.2" effort="10.0" velocity="1.0"/>
        <axis xyz="1 0 0"/>
	</joint>
	
    <transmission name="tran1">
        <type>transmission_interface/SimpleTransmission</type>
        <joint name="NaroBody_1_NaroBody_2_joint">
            <hardwareInterface>EffortJointInterface</hardwareInterface>
        </joint>
        <actuator name="motor1">
            <hardwareInterface>EffortJointInterface</hardwareInterface>
            <mechanicalReduction>1</mechanicalReduction>
        </actuator>
    </transmission>

    <link name="NaroBody_3_link">
 	    <inertial>
            <origin xyz="0 0 0" rpy="0 0 0"/>
            <mass value="0.175370624" />
            <inertia ixx="8.87413829167e-05" ixy="0.0" ixz="0.0" iyy="8.87413829167e-05" iyz="0.0" izz="8.18246025e-05"/>
        </inertial>
        <collision>
            <origin xyz="0 0 0" rpy="0 0 0"/>
            <geometry>
                <mesh filename="package://naro_description/meshes/NaroBody_3.dae"/>
            </geometry>
        </collision>
        <visual>
            <origin xyz="0 0 0" rpy="0 0 0"/>
            <geometry>
                <mesh filename="package://naro_description/meshes/NaroBody_3.dae"/>
            </geometry>
        </visual>
	</link>
    <!-- This is for color and physical properties in Gazebo, color won't work with the material tag in gazebo
    only for URDF coloring -->
    <gazebo reference="NaroBody_3_link">
        <kp>1000000.0</kp>
        <kd>1000000.0</kd>
        <mu1>10.0</mu1>
        <mu2>10.0</mu2>
    </gazebo>

    <joint name="NaroBody_2_NaroBody_3_joint" type="revolute">
    	<parent link="NaroBody_2_link"/>
    	<child link="NaroBody_3_link"/>
        <origin xyz="0 0 0.0874" rpy="0 0 0"/>
        <limit lower="-0.2" upper="0.2" effort="5.0" velocity="1.0"/>
        <axis xyz="1 0 0"/>
	</joint>
	
    <transmission name="tran2">
        <type>transmission_interface/SimpleTransmission</type>
        <joint name="NaroBody_2_NaroBody_3_joint">
            <hardwareInterface>EffortJointInterface</hardwareInterface>
        </joint>
        <actuator name="motor2">
            <hardwareInterface>EffortJointInterface</hardwareInterface>
            <mechanicalReduction>1</mechanicalReduction>
        </actuator>
    </transmission>
    
    
    <link name="Naro_caudal_fin_link">
 	    <inertial>
            <origin xyz="0 0 0" rpy="0 0 0"/>
            <mass value="0.0902944" />
            <inertia ixx="0.000220439071667" ixy="0.0" ixz="0.0" iyy="0.000220439071667" iyz="0.0" izz="0.00026615281"/>
        </inertial>
        <collision>
            <origin xyz="0 0 0" rpy="0 0 0"/>
            <geometry>
                <mesh filename="package://naro_description/meshes/Naro_caudal_fin_v2.dae"/>
            </geometry>
        </collision>
        <visual>
            <origin xyz="0 0 0" rpy="0 0 0"/>
            <geometry>
                <mesh filename="package://naro_description/meshes/Naro_caudal_fin_v2.dae"/>
            </geometry>
        </visual>
	</link>
    <!-- This is for color and physical properties in Gazebo, color won't work with the material tag in gazebo
    only for URDF coloring -->
    <gazebo reference="Naro_caudal_fin_link">
        <kp>1000000.0</kp>
        <kd>1000000.0</kd>
        <mu1>10.0</mu1>
        <mu2>10.0</mu2>
    </gazebo>

    <joint name="NaroBody_3_Naro_caudal_fin_joint" type="revolute">
    	<parent link="NaroBody_3_link"/>
    	<child link="Naro_caudal_fin_link"/>
        <origin xyz="0 0 0.05757" rpy="0 0 0"/>
        <limit lower="-0.2" upper="0.2" effort="5.0" velocity="1.0"/>
        <axis xyz="1 0 0"/>
	</joint>
	
    <transmission name="tran3">
        <type>transmission_interface/SimpleTransmission</type>
        <joint name="NaroBody_3_Naro_caudal_fin_joint">
            <hardwareInterface>EffortJointInterface</hardwareInterface>
        </joint>
        <actuator name="motor3">
            <hardwareInterface>EffortJointInterface</hardwareInterface>
            <mechanicalReduction>1</mechanicalReduction>
        </actuator>
    </transmission>
    
    
    <link name="Naro_pectoral_fin_right_link">
 	    <inertial>
            <origin xyz="0 0 0" rpy="0 0 0"/>
            <mass value="0.01123668" />
            <inertia ixx="3.15811533333e-05" ixy="0.0" ixz="0.0" iyy="3.00804033333e-05" iyz="0.0" izz="2.10075e-06"/>
        </inertial>
        <collision>
            <origin xyz="0 0 0" rpy="0 0 0"/>
            <geometry>
                <mesh filename="package://naro_description/meshes/Naro_pectoral_fin_v2.dae"/>
            </geometry>
        </collision>
        <visual>
            <origin xyz="0 0 0" rpy="0 0 0"/>
            <geometry>
                <mesh filename="package://naro_description/meshes/Naro_pectoral_fin_v2.dae"/>
            </geometry>
        </visual>
	</link>
    <!-- This is for color and physical properties in Gazebo, color won't work with the material tag in gazebo
    only for URDF coloring -->
    <gazebo reference="Naro_pectoral_fin_right_link">
        <kp>1000000.0</kp>
        <kd>1000000.0</kd>
        <mu1>10.0</mu1>
        <mu2>10.0</mu2>
        <material>Gazebo/Purple</material>
    </gazebo>

    <joint name="NaroBody_1_Naro_pectoral_fin_right_joint" type="revolute">
    	<parent link="base_link"/>
    	<child link="Naro_pectoral_fin_right_link"/>
        <origin xyz="-0.04275 -0.025 -0.03622" rpy="1.5707963267948966 0 0"/>
        <limit lower="-0.2" upper="0.2" effort="0.1" velocity="0.5"/>
        <axis xyz="0 0 1"/>
	</joint>
	
    <transmission name="tran4">
        <type>transmission_interface/SimpleTransmission</type>
        <joint name="NaroBody_1_Naro_pectoral_fin_right_joint">
            <hardwareInterface>EffortJointInterface</hardwareInterface>
        </joint>
        <actuator name="motor4">
            <hardwareInterface>EffortJointInterface</hardwareInterface>
            <mechanicalReduction>1</mechanicalReduction>
        </actuator>
    </transmission>
    
    
    <link name="Naro_pectoral_fin_left_link">
 	    <inertial>
            <origin xyz="0 0 0" rpy="0 0 0"/>
            <mass value="0.01123668" />
            <inertia ixx="3.15811533333e-05" ixy="0.0" ixz="0.0" iyy="3.00804033333e-05" iyz="0.0" izz="2.10075e-06"/>
        </inertial>
        <collision>
            <origin xyz="0 0 0" rpy="0 0 0"/>
            <geometry>
                <mesh filename="package://naro_description/meshes/Naro_pectoral_fin_sim_v2.dae"/>
            </geometry>
        </collision>
        <visual>
            <origin xyz="0 0 0" rpy="0 0 0"/>
            <geometry>
                <mesh filename="package://naro_description/meshes/Naro_pectoral_fin_sim_v2.dae"/>
            </geometry>
        </visual>
	</link>
    <!-- This is for color and physical properties in Gazebo, color won't work with the material tag in gazebo
    only for URDF coloring -->
    <gazebo reference="Naro_pectoral_fin_left_link">
        <kp>1000000.0</kp>
        <kd>1000000.0</kd>
        <mu1>10.0</mu1>
        <mu2>10.0</mu2>
    </gazebo>

    <joint name="NaroBody_1_Naro_pectoral_fin_left_joint" type="revolute">
    	<parent link="base_link"/>
    	<child link="Naro_pectoral_fin_left_link"/>
        <origin xyz="-0.04275 0.025 -0.03622" rpy="-1.5707963267948966 0 0"/>
        <limit lower="-0.2" upper="0.2" effort="0.1" velocity="0.5"/>
        <axis xyz="0 0 1"/>
	</joint>
	
    <transmission name="tran5">
        <type>transmission_interface/SimpleTransmission</type>
        <joint name="NaroBody_1_Naro_pectoral_fin_left_joint">
            <hardwareInterface>EffortJointInterface</hardwareInterface>
        </joint>
        <actuator name="motor5">
            <hardwareInterface>EffortJointInterface</hardwareInterface>
            <mechanicalReduction>1</mechanicalReduction>
        </actuator>
    </transmission>
    
    
    <link name="Naro_dorsal_fin_up_link">
 	    <inertial>
            <origin xyz="0 0 0" rpy="0 0 0"/>
            <mass value="0.00650724" />
            <inertia ixx="3.15811533333e-05" ixy="0.0" ixz="0.0" iyy="3.00804033333e-05" iyz="0.0" izz="2.10075e-06"/>
        </inertial>
        <collision>
            <origin xyz="0 0 0" rpy="0 0 0"/>
            <geometry>
                <mesh filename="package://naro_description/meshes/Naro_dorsal_fin_up.dae"/>
            </geometry>
        </collision>
        <visual>
            <origin xyz="0 0 0" rpy="0 0 0"/>
            <geometry>
                <mesh filename="package://naro_description/meshes/Naro_dorsal_fin_up.dae"/>
            </geometry>
        </visual>
	</link>
	
	<gazebo reference="Naro_dorsal_fin_up_link">
        <kp>1000000.0</kp>
        <kd>1000000.0</kd>
        <mu1>10.0</mu1>
        <mu2>10.0</mu2>
    </gazebo>
    
    <joint name="NaroBody_1_Naro_dorsal_fin_up_joint" type="fixed">
        <parent link="NaroBody_2_link"/>
        <child link="Naro_dorsal_fin_up_link"/>
        <origin xyz="0.04088 0 0.04053" rpy="0 1.3 0"/>
    </joint>
    
    
        <link name="Naro_dorsal_fin_down_link">
 	    <inertial>
            <origin xyz="0 0 0" rpy="0 0 0"/>
            <mass value="0.00641088" />
            <inertia ixx="3.15811533333e-05" ixy="0.0" ixz="0.0" iyy="3.00804033333e-05" iyz="0.0" izz="2.10075e-06"/>
        </inertial>
        <collision>
            <origin xyz="0 0 0" rpy="0 0 0"/>
            <geometry>
                <mesh filename="package://naro_description/meshes/Naro_dorsal_fin_down_v2.dae"/>
            </geometry>
        </collision>
        <visual>
            <origin xyz="0 0 0" rpy="0 0 0"/>
            <geometry>
                <mesh filename="package://naro_description/meshes/Naro_dorsal_fin_down_v2.dae"/>
            </geometry>
            <material name="purple"/>
        </visual>
	</link>
	
	<gazebo reference="Naro_dorsal_fin_down_link">
        <kp>1000000.0</kp>
        <kd>1000000.0</kd>
        <mu1>10.0</mu1>
        <mu2>10.0</mu2>
    </gazebo>
    
    <joint name="NaroBody_1_Naro_dorsal_fin_down_joint" type="fixed">
        <parent link="NaroBody_2_link"/>
        <child link="Naro_dorsal_fin_down_link"/>
        <origin xyz="-0.04088 0 0.0362" rpy="0 -1.5707963267948966 0"/>
    </joint>
    
    
    <gazebo>
        <plugin name="buoyancy_sphere" filename="libBuoyancyPlugin.so">
          <fluid_density>1001</fluid_density>
        </plugin>
    </gazebo>


</robot>